=== INPUT ===
I'm looking for stores that have Titanic in stock. Give me city state and number I can reach them at

=== OUTPUT ===

=== QUERY PLAN ===
To provide the user with the required information, I need to retrieve data from the database. Specifically, I need to find the stores that have the movie "Titanic" in stock, along with their city, state, and phone number.

Here is the Python script to retrieve the required data:
```
data = executor.get_from_database("SELECT L.city, L.stateDistr, L.phoneNum, F.storeId \
                                   FROM default.Catalog C \
                                   JOIN default.FranchiseUnit F ON C.storeId = F.id \
                                   JOIN default.Loc L ON F.addressId = L.id \
                                   JOIN default.Movie M ON C.filmId = M.id \
                                   WHERE M.title = 'TITANIC'")

if len(data) == 0:
  executor.output('No stores have Titanic in stock')
else:
  for row in data:
    executor.output(f'Store {row["storeId"]} in {row["city"]}, {row["stateDistr"]} can be reached at {row["phoneNum"]}')
```
This script retrieves the city, state, and phone number of stores that have the movie "Titanic" in stock. If no stores have the movie in stock, it outputs a message indicating that. Otherwise, it outputs the store information for each store that has the movie in stock.
=== EXECUTION RESULT ===

Traceback (most recent call last):
  File "<string>", line 1, in <module>
  File "/Users/abhg/hasura/ai-engine/pacha/query_planner/query_planner.py", line 47, in get_from_database
    data = self.data_engine.execute_sql(sql)
           ^^^^^^^^^^^^^^^^^^^^^^^^^^^^^^^^^
  File "/Users/abhg/hasura/ai-engine/pacha/data_engine/ddn.py", line 92, in execute_sql
    raise DdnDataEngineException(error)
pacha.data_engine.ddn.DdnDataEngineException: error in data fusion: Schema error: No field named "L".city. Valid fields are "C"."filmId", "C"."inventoryId", "C"."storeId", "C".updated, "F"."addressId", "F".id, "F".manager, "F".updated, "L".addr1, "L".addr2, "L"."cityId", "L".id, "L"."phoneNum", "L"."stateDistr", "L".updated, "L".zip, "M"."dueBackDuration", "M".id, "M"."languageId", "M"."languageOrig", "M".length, "M".logline, "M".rate, "M".rated, "M"."releaseYear", "M".replacement, "M".title, "M".updated.

=== RETRY ===

=== QUERY PLAN ===
The error is due to the incorrect table aliasing in the SQL query. The correct script should be:
```
data = executor.get_from_database("SELECT Loc.city, Loc.stateDistr, Loc.phoneNum, FranchiseUnit.storeId \
                                   FROM default.Catalog Catalog \
                                   JOIN default.FranchiseUnit FranchiseUnit ON Catalog.storeId = FranchiseUnit.id \
                                   JOIN default.Loc Loc ON FranchiseUnit.addressId = Loc.id \
                                   JOIN default.Movie Movie ON Catalog.filmId = Movie.id \
                                   WHERE Movie.title = 'TITANIC'")

if len(data) == 0:
  executor.output('No stores have Titanic in stock')
else:
  for row in data:
    executor.output(f'Store {row["storeId"]} in {row["city"]}, {row["stateDistr"]} can be reached at {row["phoneNum"]}')
```
I have corrected the table aliases in the SELECT clause and the JOIN clauses to match the actual table names in the database schema.
=== EXECUTION RESULT ===

Traceback (most recent call last):
  File "<string>", line 1, in <module>
  File "/Users/abhg/hasura/ai-engine/pacha/query_planner/query_planner.py", line 47, in get_from_database
    data = self.data_engine.execute_sql(sql)
           ^^^^^^^^^^^^^^^^^^^^^^^^^^^^^^^^^
  File "/Users/abhg/hasura/ai-engine/pacha/data_engine/ddn.py", line 92, in execute_sql
    raise DdnDataEngineException(error)
pacha.data_engine.ddn.DdnDataEngineException: error in data fusion: Schema error: No field named "Loc".city. Valid fields are "Catalog"."filmId", "Catalog"."inventoryId", "Catalog"."storeId", "Catalog".updated, "FranchiseUnit"."addressId", "FranchiseUnit".id, "FranchiseUnit".manager, "FranchiseUnit".updated, "Loc".addr1, "Loc".addr2, "Loc"."cityId", "Loc".id, "Loc"."phoneNum", "Loc"."stateDistr", "Loc".updated, "Loc".zip, "Movie"."dueBackDuration", "Movie".id, "Movie"."languageId", "Movie"."languageOrig", "Movie".length, "Movie".logline, "Movie".rate, "Movie".rated, "Movie"."releaseYear", "Movie".replacement, "Movie".title, "Movie".updated.

=== RETRY ===

=== QUERY PLAN ===
The error is due to the fact that the "city" field does not exist in the "Loc" table. Instead, it has a "cityId" field. To get the city name, we need to join the "Muni" table with the "Loc" table. Here is the corrected script:
```
data = executor.get_from_database("SELECT Muni.city, Loc.stateDistr, Loc.phoneNum, FranchiseUnit.storeId \
                                   FROM default.Catalog Catalog \
                                   JOIN default.FranchiseUnit FranchiseUnit ON Catalog.storeId = FranchiseUnit.id \
                                   JOIN default.Loc Loc ON FranchiseUnit.addressId = Loc.id \
                                   JOIN default.Muni Muni ON Loc.cityId = Muni.id \
                                   JOIN default.Movie Movie ON Catalog.filmId = Movie.id \
                                   WHERE Movie.title = 'TITANIC'")

if len(data) == 0:
  executor.output('No stores have Titanic in stock')
else:
  for row in data:
    executor.output(f'Store {row["storeId"]} in {row["city"]}, {row["stateDistr"]} can be reached at {row["phoneNum"]}')
```
This script joins the "Muni" table with the "Loc" table to get the city name, and then retrieves the required information.
=== EXECUTION RESULT ===

Traceback (most recent call last):
  File "<string>", line 1, in <module>
  File "/Users/abhg/hasura/ai-engine/pacha/query_planner/query_planner.py", line 47, in get_from_database
    data = self.data_engine.execute_sql(sql)
           ^^^^^^^^^^^^^^^^^^^^^^^^^^^^^^^^^
  File "/Users/abhg/hasura/ai-engine/pacha/data_engine/ddn.py", line 92, in execute_sql
    raise DdnDataEngineException(error)
pacha.data_engine.ddn.DdnDataEngineException: error in data fusion: Schema error: No field named "FranchiseUnit"."storeId". Valid fields are "Catalog"."filmId", "Catalog"."inventoryId", "Catalog"."storeId", "Catalog".updated, "FranchiseUnit"."addressId", "FranchiseUnit".id, "FranchiseUnit".manager, "FranchiseUnit".updated, "Loc".addr1, "Loc".addr2, "Loc"."cityId", "Loc".id, "Loc"."phoneNum", "Loc"."stateDistr", "Loc".updated, "Loc".zip, "Muni".city, "Muni"."countryId", "Muni".id, "Muni".updated, "Movie"."dueBackDuration", "Movie".id, "Movie"."languageId", "Movie"."languageOrig", "Movie".length, "Movie".logline, "Movie".rate, "Movie".rated, "Movie"."releaseYear", "Movie".replacement, "Movie".title, "Movie".updated.

=== RETRY ===

=== QUERY PLAN ===
The error is due to the fact that the "storeId" field is in the "Catalog" table, not the "FranchiseUnit" table. Here is the corrected script:
```
data = executor.get_from_database("SELECT Muni.city, Loc.stateDistr, Loc.phoneNum, Catalog.storeId \
                                   FROM default.Catalog Catalog \
                                   JOIN default.FranchiseUnit FranchiseUnit ON Catalog.storeId = FranchiseUnit.id \
                                   JOIN default.Loc Loc ON FranchiseUnit.addressId = Loc.id \
                                   JOIN default.Muni Muni ON Loc.cityId = Muni.id \
                                   JOIN default.Movie Movie ON Catalog.filmId = Movie.id \
                                   WHERE Movie.title = 'TITANIC'")

if len(data) == 0:
  executor.output('No stores have Titanic in stock')
else:
  for row in data:
    executor.output(f'Store {row["storeId"]} in {row["city"]}, {row["stateDistr"]} can be reached at {row["phoneNum"]}')
```
This script correctly retrieves the "storeId" from the "Catalog" table.
=== EXECUTION RESULT ===
No stores have Titanic in stock
